<?xml version="1.0" encoding="utf-8"?>
<!-- =================================================================================== -->
<!-- |    This document was autogenerated by xacro from g500_eca_pv.xacro              | -->
<!-- |    EDITING THIS FILE BY HAND IS NOT RECOMMENDED                                 | -->
<!-- =================================================================================== -->
<robot name="g500_arm" xmlns:xacro="http://www.ros.org/wiki/xacro">
  <!-- base link is the body of the robot -->
  <!--
  <link name="base_link">
    <visual>
      <origin rpy="0 0 0" xyz="0 0 0"/>
      <geometry>
          <sphere radius="0.03"/>
      </geometry>
    </visual>
  </link>

  <joint name="baselink_to_base" type="revolute">
    <parent link="base_link"/>
    <child link="base"/>
    <axis xyz="1 0 0"/>
    <origin rpy="0.045 0 0" xyz="0.25 0 0"/>
    <limit effort="30.0" lower="-3.14" upper="3.14" velocity="0.025"/>
  </joint> -->
  <!--
  <link name="base">
    <visual>
      <origin rpy="0 0 0" xyz="0.0 0 0.0"/>
      <geometry>
        <mesh filename="package://g500_arm_description/meshes/robot/ECA/arm0.3ds" scale="0.001 0.001 0.001"/>
      </geometry>
      <material name="Grey">
        <color rgba="0.5 0.5 0.5 1.0"/>
      </material>
    </visual>
    <collision>
      <origin rpy="0 0 0" xyz="-0.2 0 0.0"/>
      <geometry>
        <box size="0.25 0.12 0.2" />
      </geometry>
    </collision>
  </link> -->
  <link name="base_link">
    <visual>
      <origin rpy="0 0 0" xyz="0 0 0"/>
      <geometry>
        <box size="0.25 0.12 0.2"/>
      </geometry>
    </visual>
    <collision>
      <origin rpy="0 0 0" xyz="0 0 0.0"/>
      <geometry>
        <box size="0.25 0.12 0.2"/>
      </geometry>
    </collision>
    <inertial>
      <mass value="1"/>
      <inertia ixx="1.0" ixy="0.0" ixz="0.0" iyy="0.5" iyz="0.0" izz="1.0"/>
    </inertial>
  </link>
  <joint name="q1" type="revolute">
    <parent link="base_link"/>
    <child link="L0"/>
    <axis xyz="0 0 1"/>
    <origin rpy="0.0 0.0 0.0" xyz="0.125 0.0 0.0"/>
    <limit effort="300" lower="-0.43" upper="1.54" velocity="0.025"/>
  </joint>
  <transmission name="q1_joint_trans">
    <type>transmission_interface/SimpleTransmission</type>
    <joint name="q1">
      <hardwareInterface>PositionJointInterface</hardwareInterface>
    </joint>
    <actuator name="motor1">
      <hardwareInterface>PositionJointInterface</hardwareInterface>
      <mechanicalReduction>1</mechanicalReduction>
    </actuator>
  </transmission>
  <!-- 
  <link name="L0">
  	<visual>
      <origin xyz="0.0 0 0" rpy="0 0 0"/>
      <geometry>
        <mesh filename="package://g500_arm_description/meshes/robot/ECA/arm1.3ds" scale="0.001 0.001 0.001"/>
      </geometry>
      <material name="LightGrey">
        <color rgba="0.75 0.75 0.75 1.0"/>
      </material>
    </visual>
    <collision>
      <origin xyz="0.18 0 0" rpy="0 0 0"/>
		  <geometry>
				<box size="0.2 0.1 0.18" />
			</geometry>
		</collision>
   </link> -->
  <!-- JUST MAKING SURE EVERYTHING IS FINE -->
  <link name="L0">
    <visual>
      <origin rpy="0 0 0" xyz="0.1 0 0"/>
      <geometry>
        <box size="0.2 0.1 0.18"/>
      </geometry>
      <material name="LightGrey">
        <color rgba="0.75 0.75 0.75 1.0"/>
      </material>
    </visual>
    <collision>
      <origin rpy="0 0 0" xyz="0.1 0 0"/>
      <geometry>
        <box size="0.2 0.1 0.18"/>
      </geometry>
    </collision>
    <inertial>
      <mass value="1"/>
      <inertia ixx="1.0" ixy="0.0" ixz="0.0" iyy="0.5" iyz="0.0" izz="1.0"/>
    </inertial>
  </link>
  <joint name="q2" type="revolute">
    <parent link="L0"/>
    <child link="L1"/>
    <axis xyz="0 0 1"/>
    <origin rpy="-1.57 0.0 0.0" xyz="0.2 0.0 0.0"/>
    <limit effort="300" lower="-0.10" upper="1.45" velocity="0.025"/>
  </joint>
  <transmission name="q2_joint_trans">
    <type>transmission_interface/SimpleTransmission</type>
    <joint name="q2">
      <hardwareInterface>PositionJointInterface</hardwareInterface>
    </joint>
    <actuator name="motor2">
      <hardwareInterface>PositionJointInterface</hardwareInterface>
      <mechanicalReduction>1</mechanicalReduction>
    </actuator>
  </transmission>
   --&gt;

  <!--
   <link name="L1">
    <visual>
      <origin rpy="0 0 0" xyz="0.0 0.0 0.0"/>
      <geometry>
        <mesh filename="package://g500_arm_description/meshes/robot/ECA/arm2.3ds" scale="0.001 0.001 0.001"/>
      </geometry>
      <material name="Grey">
        <color rgba="0.5 0.5 0.5 1.0"/>
      </material>
    </visual>
    <collision>
      <origin rpy="0 0 0" xyz="0.2 0 0.0"/>
		<geometry>
      <box size="0.3 0.2 0.15" />
		</geometry>
	 </collision>
  </link> -->
  <!-- JUST MAKING SURE EVERYTHING IS FINE -->
  <link name="L1">
    <visual>
      <origin rpy="0 0 0" xyz="0.15 0.0 0.0"/>
      <geometry>
        <box size="0.3 0.2 0.15"/>
      </geometry>
      <material name="Grey">
        <color rgba="0.5 0.5 0.5 1.0"/>
      </material>
    </visual>
    <collision>
      <origin rpy="0 0 0" xyz="0.15 0 0.0"/>
      <geometry>
        <box size="0.3 0.2 0.15"/>
      </geometry>
    </collision>
    <inertial>
      <mass value="1"/>
      <inertia ixx="1.0" ixy="0.0" ixz="0.0" iyy="0.5" iyz="0.0" izz="1.0"/>
    </inertial>
  </link>
  <joint name="q3" type="revolute">
    <parent link="L1"/>
    <child link="L2"/>
    <axis xyz="0 0 1"/>
    <origin rpy="0.0 0 0" xyz="0.3 0.0 0.0"/>
    <limit effort="300" lower="-1.22" upper="0.645" velocity="0.09"/>
  </joint>
  <transmission name="q3_joint_trans">
    <type>transmission_interface/SimpleTransmission</type>
    <joint name="q3">
      <hardwareInterface>PositionJointInterface</hardwareInterface>
    </joint>
    <actuator name="motor3">
      <hardwareInterface>PositionJointInterface</hardwareInterface>
      <mechanicalReduction>1</mechanicalReduction>
    </actuator>
  </transmission>
  <!--
  <link name="L2">
    <visual>
      <origin rpy="0 0 0" xyz="0.0 0.0 0.0"/>
        <geometry>
          <mesh filename="package://g500_arm_description/meshes/robot/ECA/arm3.3ds" scale="0.001 0.001 0.001"/>
        </geometry>
        <material name="LightGrey">
          <color rgba="0.75 0.75 0.75 1.0"/>
        </material>
    </visual>
    <collision>
      <origin rpy="0 0 0" xyz="0.0 0.0 0.0"/>
      <geometry>
        <box size="0.15 0.08 0.12" />
      </geometry>
    </collision>
  </link> -->
  <!-- JUST MAKING SURE EVERYTHING IS FINE -->
  <link name="L2">
    <visual>
      <origin rpy="0 0 0" xyz="0.075 0.0 0.0"/>
      <geometry>
        <box size="0.15 0.08 0.12"/>
      </geometry>
      <material name="LightGrey">
        <color rgba="0.75 0.75 0.75 1.0"/>
      </material>
    </visual>
    <collision>
      <origin rpy="0 0 0" xyz="0.075 0.0 0.0"/>
      <geometry>
        <box size="0.15 0.08 0.12"/>
      </geometry>
    </collision>
    <inertial>
      <mass value="1"/>
      <inertia ixx="1.0" ixy="0.0" ixz="0.0" iyy="0.5" iyz="0.0" izz="1.0"/>
    </inertial>
  </link>
  <joint name="q4" type="revolute">
    <parent link="L2"/>
    <child link="L3"/>
    <axis xyz="0 0 1"/>
    <origin rpy="1.57 0 0" xyz="0.15 0.0 0.0"/>
    <limit effort="300" lower="-3.12" upper="3.12" velocity="0.09"/>
  </joint>
  <transmission name="q4_joint_trans">
    <type>transmission_interface/SimpleTransmission</type>
    <joint name="q4">
      <hardwareInterface>PositionJointInterface</hardwareInterface>
    </joint>
    <actuator name="motor4">
      <hardwareInterface>PositionJointInterface</hardwareInterface>
      <mechanicalReduction>1</mechanicalReduction>
    </actuator>
  </transmission>
   --&gt;


  <!--
  <link name="L3">
    <visual>
      <origin rpy="0 0 0" xyz="0.0 0.0 0.0"/>
      <geometry>
        <mesh filename="package://g500_arm_description/meshes/robot/ECA/arm4.3ds" scale="0.001 0.001 0.001"/>
      </geometry>
      <material name="LightBlack">
        <color rgba="0.2 0.2 0.2 1.0"/>
      </material>
    </visual>
    <collision>
      <origin rpy="0 0 0" xyz="0 0 0.15"/>
      <geometry>
        <box size="0.12 0.2 0.28" />
      </geometry>
    </collision>
  </link> -->
  <link name="L3">
    <visual>
      <origin rpy="0 0 0" xyz="0.06 0.0 0.15"/>
      <geometry>
        <box size="0.12 0.2 0.28"/>
      </geometry>
      <material name="LightBlack">
        <color rgba="0.2 0.2 0.2 1.0"/>
      </material>
    </visual>
    <collision>
      <origin rpy="0 0 0" xyz="0.06 0 0.15"/>
      <geometry>
        <box size="0.12 0.2 0.28"/>
      </geometry>
    </collision>
    <inertial>
      <mass value="1"/>
      <inertia ixx="1.0" ixy="0.0" ixz="0.0" iyy="0.5" iyz="0.0" izz="1.0"/>
    </inertial>
  </link>
  <link name="grasping_frame">
    <inertial>
      <origin rpy="0 0 0" xyz="0 0 0"/>
      <mass value="0.0001"/>
      <cuboid_inertia mass="0.0001" x="0.001" y="0.001" z="0.001"/>
      <inertia ixx="1.0" ixy="0.0" ixz="0.0" iyy="100.0" iyz="0.0" izz="1.0"/>
    </inertial>
    <visual>
      <origin xyz="0 0 0"/>
      <geometry>
        <box size="0.02 0.02 0.02"/>
      </geometry>
      <material name="White"/>
    </visual>
  </link>
  <joint name="grasping_frame_joint" type="fixed">
    <parent link="L2"/>
    <child link="grasping_frame"/>
    <origin rpy="0 0 0" xyz="0.28 -0.15 0"/>
  </joint>
  <!-- frames in the center of the camera -->
  <joint name="rgbd_camera_joint" type="fixed">
    <origin rpy="0 1.308996939 0" xyz="0.1 0 1"/>
    <parent link="base_link"/>
    <child link="rgbd_camera_link"/>
  </joint>
  <link name="rgbd_camera_link">
    <inertial>
      <origin rpy="0 0 0" xyz="-0.00936000000 -0.00003000000 -0.00273000000"/>
      <mass value="0.21970000000"/>
      <inertia ixx="0.00000429247" ixy="0.00000000000" ixz="0.00000002565" iyy="0.00000008027" iyz="0.00000000000" izz="0.00000427339"/>
    </inertial>
    <visual>
      <origin rpy="0 0 0" xyz="0 0 0"/>
      <geometry>
        <mesh filename="package://mastering_ros_robot_description_pkg/meshes/sensors/xtion_pro_live/xtion_pro_live.dae"/>
      </geometry>
      <material name="DarkGrey"/>
    </visual>
  </link>
  <joint name="rgbd_camera_optical_joint" type="fixed">
    <origin rpy="-1.57079632679 0 -1.57079632679" xyz="0 0 0"/>
    <parent link="rgbd_camera_link"/>
    <child link="rgbd_camera_optical_frame"/>
  </joint>
  <link name="rgbd_camera_optical_frame">
    <inertial>
      <origin rpy="0 0 0" xyz="0 0 0"/>
      <mass value="0.001"/>
      <inertia ixx="0.00001" ixy="0" ixz="0" iyy="0.00001" iyz="0" izz="0.00001"/>
    </inertial>
  </link>
  <!-- Depth sensor frames -->
  <joint name="rgbd_camera_depth_joint" type="fixed">
    <origin rpy="0 0 0" xyz="0.0 0.049 0.0"/>
    <parent link="rgbd_camera_link"/>
    <child link="rgbd_camera_depth_frame"/>
  </joint>
  <link name="rgbd_camera_depth_frame">
    <inertial>
      <origin rpy="0 0 0" xyz="0 0 0"/>
      <mass value="0.001"/>
      <inertia ixx="0.00001" ixy="0" ixz="0" iyy="0.00001" iyz="0" izz="0.00001"/>
    </inertial>
  </link>
  <joint name="rgbd_camera_depth_optical_joint" type="fixed">
    <origin rpy="-1.57079632679 0.0 -1.57079632679" xyz="0 0 0"/>
    <parent link="rgbd_camera_depth_frame"/>
    <child link="rgbd_camera_depth_optical_frame"/>
  </joint>
  <link name="rgbd_camera_depth_optical_frame">
    <inertial>
      <origin rpy="0 0 0" xyz="0 0 0"/>
      <mass value="0.001"/>
      <inertia ixx="0.00001" ixy="0" ixz="0" iyy="0.00001" iyz="0" izz="0.00001"/>
    </inertial>
  </link>
  <!-- RGB sensor frames -->
  <joint name="rgbd_camera_rgb_joint" type="fixed">
    <origin rpy="0 0 0" xyz="0.0 0.022 0.0"/>
    <parent link="rgbd_camera_link"/>
    <child link="rgbd_camera_rgb_frame"/>
  </joint>
  <link name="rgbd_camera_rgb_frame">
    <inertial>
      <origin rpy="0 0 0" xyz="0 0 0"/>
      <mass value="0.001"/>
      <inertia ixx="0.00001" ixy="0" ixz="0" iyy="0.00001" iyz="0" izz="0.00001"/>
    </inertial>
  </link>
  <joint name="rgbd_camera_rgb_optical_joint" type="fixed">
    <origin rpy="-1.57079632679 0.0 -1.57079632679" xyz="0 0 0"/>
    <parent link="rgbd_camera_rgb_frame"/>
    <child link="rgbd_camera_rgb_optical_frame"/>
  </joint>
  <link name="rgbd_camera_rgb_optical_frame">
    <inertial>
      <origin rpy="0 0 0" xyz="0 0 0"/>
      <mass value="0.001"/>
      <inertia ixx="0.00001" ixy="0" ixz="0" iyy="0.00001" iyz="0" izz="0.00001"/>
    </inertial>
  </link>
  <gazebo reference="rgbd_camera_link">
    <!-- Depth (IR) -->
    <sensor name="rgbd_camera_frame_sensor" type="depth">
      <always_on>true</always_on>
      <update_rate>6.0</update_rate>
      <camera>
        <horizontal_fov>1.01229096616</horizontal_fov>
        <image>
          <format>R8G8B8</format>
          <width>320</width>
          <height>240</height>
        </image>
        <clip>
          <near>0.05</near>
          <far>4.0</far>
        </clip>
      </camera>
      <plugin filename="libgazebo_ros_openni_kinect.so" name="rgbd_camera_frame_controller">
        <alwaysOn>true</alwaysOn>
        <updateRate>6.0</updateRate>
        <cameraName>rgbd_camera</cameraName>
        <imageTopicName>ir/image_raw</imageTopicName>
        <cameraInfoTopicName>ir/camera_info</cameraInfoTopicName>
        <depthImageTopicName>depth/image_raw</depthImageTopicName>
        <depthImageCameraInfoTopicName>depth/camera_info</depthImageCameraInfoTopicName>
        <pointCloudTopicName>depth/points</pointCloudTopicName>
        <frameName>rgbd_camera_optical_frame</frameName>
        <pointCloudCutoff>0.05</pointCloudCutoff>
        <pointCloudCutoffMax>5</pointCloudCutoffMax>
        <rangeMax>4.0</rangeMax>
        <!-- Distortion parameters not supported in gazebo 1.9.* plugins -->
        <!--distortionK1>0.00000001</distortionK1>
          <distortionK2>0.00000001</distortionK2>
          <distortionK3>0.00000001</distortionK3>
          <distortionT1>0.00000001</distortionT1>
          <distortionT2>0.00000001</distortionT2-->
      </plugin>
    </sensor>
    <!-- RGB -->
    <sensor name="rgbd_camera_frame_sensor" type="depth">
      <always_on>true</always_on>
      <update_rate>6.0</update_rate>
      <camera>
        <horizontal_fov>1.01229096616</horizontal_fov>
        <image>
          <format>R8G8B8</format>
          <width>320</width>
          <height>240</height>
        </image>
        <clip>
          <near>0.05</near>
          <far>4.0</far>
        </clip>
      </camera>
      <plugin filename="libgazebo_ros_openni_kinect.so" name="rgbd_camera_frame_controller">
        <alwaysOn>true</alwaysOn>
        <updateRate>6.0</updateRate>
        <cameraName>rgbd_camera</cameraName>
        <imageTopicName>rgb/image_raw</imageTopicName>
        <cameraInfoTopicName>rgb/camera_info</cameraInfoTopicName>
        <pointCloudTopicName>rgb/points</pointCloudTopicName>
        <depthImageTopicName>depth/image_raw</depthImageTopicName>
        <depthImageCameraInfoTopicName>depth/camera_info</depthImageCameraInfoTopicName>
        <frameName>rgbd_camera_optical_frame</frameName>
        <pointCloudCutoff>0.05</pointCloudCutoff>
        <pointCloudCutoffMax>5</pointCloudCutoffMax>
        <rangeMax>4.0</rangeMax>
      </plugin>
    </sensor>
  </gazebo>
  <gazebo plugin="libgazebo_ros_control.so" reference="gazebo_ros_control">
    <robotNameSpace>/g500_arm</robotNameSpace>
  </gazebo>
  <!--
  <joint name="jaw" type="revolute">
    <parent link="L3"/>
    <child link="L4"/>
    <axis xyz="0 1 0"/>
    <origin rpy="0 0 0" xyz="0.0 0.0 0.328"/>
    <limit effort="30.0" lower="-3.14" upper="3.14" velocity="0.025"/>
  </joint>

  <link name="L4">
    <visual>
      <origin rpy="0 0 0" xyz="0 0 0"/>
      <geometry>
          <sphere radius="0.03"/>
      </geometry>
    </visual>
  </link> -->
</robot>
